tests/1buy-1sell-conc-2thread.in
2
o
0 B 127 GOOG 2705 30
1 S 128 GOOG 2705 30
1 B 129 GOOG 2705 30
0 S 130 GOOG 2705 30
0 B 131 GOOG 2705 30
1 S 132 GOOG 2705 30
1 B 133 GOOG 2705 30
0 S 134 GOOG 2705 30
1 B 135 GOOG 2705 30
0 S 136 GOOG 2705 30
1 B 137 GOOG 2705 30
0 S 138 GOOG 2705 30
0 B 139 GOOG 2705 30
1 S 140 GOOG 2705 30
0 B 141 GOOG 2705 30
1 S 142 GOOG 2705 30
0 B 143 GOOG 2705 30
1 S 144 GOOG 2705 30
1 B 145 GOOG 2705 30
0 S 146 GOOG 2705 30
0 B 147 GOOG 2705 30
1 S 148 GOOG 2705 30
1 B 149 GOOG 2705 30
0 S 150 GOOG 2705 30
0 B 151 GOOG 2705 30
1 S 152 GOOG 2705 30
1 B 153 GOOG 2705 30
0 S 154 GOOG 2705 30
1 B 155 GOOG 2705 30
0 S 156 GOOG 2705 30
1 B 157 GOOG 2705 30
0 S 158 GOOG 2705 30
0 B 159 GOOG 2705 30
1 S 160 GOOG 2705 30
0 B 161 GOOG 2705 30
1 S 162 GOOG 2705 30
0 B 163 GOOG 2705 30
1 S 164 GOOG 2705 30
1 B 165 GOOG 2705 30
0 S 166 GOOG 2705 30
0 B 167 GOOG 2705 30
1 S 168 GOOG 2705 30
1 B 169 GOOG 2705 30
0 S 170 GOOG 2705 30
0 B 171 GOOG 2705 30
1 S 172 GOOG 2705 30
1 B 173 GOOG 2705 30
0 S 174 GOOG 2705 30
1 B 175 GOOG 2705 30
0 S 176 GOOG 2705 30
1 B 177 GOOG 2705 30
0 S 178 GOOG 2705 30
0 B 179 GOOG 2705 30
1 S 180 GOOG 2705 30
0 B 181 GOOG 2705 30
1 S 182 GOOG 2705 30
0 B 183 GOOG 2705 30
1 S 184 GOOG 2705 30
1 B 185 GOOG 2705 30
0 S 186 GOOG 2705 30
0 B 187 GOOG 2705 30
1 S 188 GOOG 2705 30
1 B 189 GOOG 2705 30
0 S 190 GOOG 2705 30
0 B 191 GOOG 2705 30
1 S 192 GOOG 2705 30
1 B 193 GOOG 2705 30
0 S 194 GOOG 2705 30
1 B 195 GOOG 2705 30
0 S 196 GOOG 2705 30
1 B 197 GOOG 2705 30
0 S 198 GOOG 2705 30
0 B 199 GOOG 2705 30
1 S 200 GOOG 2705 30
0 B 201 GOOG 2705 30
1 S 202 GOOG 2705 30
0 B 203 GOOG 2705 30
1 S 204 GOOG 2705 30
1 B 205 GOOG 2705 30
0 S 206 GOOG 2705 30
x
