tests/1buy-manySell-conc-5thread.in
# multiple threads, all trying to buy the same instrument
5
o
0 B 127 GOOG 2705 30
3 S 128 GOOG 2705 30
4 S 129 GOOG 2705 30
1 S 130 GOOG 2705 30
2 S 131 GOOG 2705 30
0 B 132 GOOG 2705 30
3 S 133 GOOG 2705 30
4 S 134 GOOG 2705 30
1 S 135 GOOG 2705 30
2 S 136 GOOG 2705 30
0 B 137 GOOG 2705 30
3 S 138 GOOG 2705 30
4 S 139 GOOG 2705 30
1 S 140 GOOG 2705 30
2 S 141 GOOG 2705 30
0 B 142 GOOG 2705 30
3 S 143 GOOG 2705 30
4 S 144 GOOG 2705 30
1 S 145 GOOG 2705 30
2 S 146 GOOG 2705 30
0 B 147 GOOG 2705 30
3 S 148 GOOG 2705 30
4 S 149 GOOG 2705 30
1 S 150 GOOG 2705 30
2 S 151 GOOG 2705 30
0 B 152 GOOG 2705 30
3 S 153 GOOG 2705 30
4 S 154 GOOG 2705 30
1 S 155 GOOG 2705 30
2 S 156 GOOG 2705 30
0 B 157 GOOG 2705 30
3 S 158 GOOG 2705 30
4 S 159 GOOG 2705 30
1 S 160 GOOG 2705 30
2 S 161 GOOG 2705 30
0 B 162 GOOG 2705 30
3 S 163 GOOG 2705 30
4 S 164 GOOG 2705 30
1 S 165 GOOG 2705 30
2 S 166 GOOG 2705 30
0 B 167 GOOG 2705 30
3 S 168 GOOG 2705 30
4 S 169 GOOG 2705 30
1 S 170 GOOG 2705 30
2 S 171 GOOG 2705 30
0 B 172 GOOG 2705 30
3 S 173 GOOG 2705 30
4 S 174 GOOG 2705 30
1 S 175 GOOG 2705 30
2 S 176 GOOG 2705 30
0 B 177 GOOG 2705 30
3 S 178 GOOG 2705 30
4 S 179 GOOG 2705 30
1 S 180 GOOG 2705 30
2 S 191 GOOG 2705 30
0 B 192 GOOG 2705 30
3 S 193 GOOG 2705 30
4 S 194 GOOG 2705 30
1 S 195 GOOG 2705 30
2 S 196 GOOG 2705 30
x
