tests/2buy-1sell-conc-3thread-partial.in
3
o
0 B 123 AAPL 2700 20
1 S 124 AAPL 2700 100
2 B 125 AAPL 2700 80
0 B 126 AAPL 2700 20
1 S 127 AAPL 2700 100
2 B 128 AAPL 2700 80
0 B 129 AAPL 2700 20
1 S 130 AAPL 2700 100
2 B 131 AAPL 2700 80
0 B 132 AAPL 2700 20
1 S 133 AAPL 2700 100
2 B 134 AAPL 2700 90
0 B 135 AAPL 2700 20
1 S 136 AAPL 2700 100
2 B 137 AAPL 2700 90
0 B 138 AAPL 2700 20
1 S 139 AAPL 2700 100
2 B 140 AAPL 2700 90
0 B 143 AAPL 2700 20
1 S 144 AAPL 2700 100
2 B 145 AAPL 2700 90
0 B 146 AAPL 2700 20
1 S 147 AAPL 2700 100
2 B 148 AAPL 2700 90
0 B 149 AAPL 2700 20
1 S 150 AAPL 2700 100
2 B 151 AAPL 2700 80
0 B 152 AAPL 2700 20
1 S 153 AAPL 2700 100
2 B 154 AAPL 2700 80
0 B 155 AAPL 2700 20
1 S 156 AAPL 2700 100
2 B 157 AAPL 2700 80
0 B 158 AAPL 2700 20
1 S 159 AAPL 2700 100
2 B 160 AAPL 2700 80
x
