tests/add-cancel-add-conc.in
3
o
0 B 125 GOOG 2705 30
0 C 125
2 S 126 GOOG 2705 30
0 B 127 GOOG 2705 30
0 C 127
2 S 129 GOOG 2705 30
0 B 130 GOOG 2705 30
0 C 130
1 S 132 GOOG 2705 30
0 B 133 GOOG 2705 30
0 C 133
1 S 135 GOOG 2705 30
0 B 136 GOOG 2705 30
0 C 136
1 S 137 GOOG 2705 30
0 B 138 GOOG 2705 30
0 C 138
2 S 139 GOOG 2705 30
0 B 140 GOOG 2705 30
0 C 140
2 S 141 GOOG 2705 30
0 B 142 GOOG 2705 30
0 C 142
2 S 143 GOOG 2705 30
0 B 144 GOOG 2705 30
0 C 144
1 S 146 GOOG 2705 30
0 B 147 GOOG 2705 30
0 C 147
1 S 148 GOOG 2705 30
0 B 149 GOOG 2705 30
0 C 149
1 S 150 GOOG 2705 30
0 B 151 GOOG 2705 30
0 C 151
2 S 152 GOOG 2705 30
0 B 153 GOOG 2705 30
0 C 153
1 S 154 GOOG 2705 30
0 B 155 GOOG 2705 30
0 C 155
2 S 156 GOOG 2705 30
x
