tests/cancel-test.in
6
o
0 B 1 AAPL 2705 29
0 C 1
0 S 2 AAPL 2705 30
0 B 3 MSFT 2705 29
0 C 3
0 S 4 MSFT 2705 30
1 B 5 AAPL 2705 29
1 C 5
1 S 6 AAPL 2705 30
1 B 7 MSFT 2705 29
1 C 7
1 S 8 MSFT 2705 30
2 B 9 AAPL 2705 29
2 C 9
2 S 10 AAPL 2705 30
2 B 11 MSFT 2705 29
2 C 11
2 S 12 MSFT 2705 30
3 B 13 AAPL 2705 29
3 C 13
3 S 14 AAPL 2705 30
3 B 15 MSFT 2705 29
3 C 15
3 S 16 MSFT 2705 30
4 B 17 AAPL 2705 29
4 C 17
4 S 18 AAPL 2705 30
4 B 19 MSFT 2705 29
4 C 19
4 S 20 MSFT 2705 30
5 B 21 AAPL 2705 29
5 C 21
5 S 22 AAPL 2705 30
5 B 23 MSFT 2705 29
5 C 23
5 S 24 MSFT 2705 30
.
x
