tests/exec-reject-cancel-conc.in
5
o
0 B 125 GOOG 2705 30
1 S 126 GOOG 2705 30
0 C 125
0 B 128 GOOG 2705 30
2 S 129 GOOG 2705 30
0 C 128
0 B 131 GOOG 2705 30
1 S 162 GOOG 2705 30
0 C 131
0 B 132 GOOG 2705 30
3 S 133 GOOG 2705 30
0 C 132
0 B 134 GOOG 2705 30
1 S 135 GOOG 2705 30
0 C 134
0 B 136 GOOG 2705 30
4 S 177 GOOG 2705 30
0 C 136
0 B 137 GOOG 2705 30
2 S 138 GOOG 2705 30
0 C 137
1 B 139 GOOG 2705 30
1 S 140 GOOG 2705 30
1 C 139
3 B 141 GOOG 2705 30
1 S 142 GOOG 2705 30
3 C 141
3 B 143 GOOG 2705 30
1 S 144 GOOG 2705 30
3 C 143
1 B 145 GOOG 2705 30
4 S 146 GOOG 2705 30
1 C 145
2 B 147 GOOG 2705 30
2 S 148 GOOG 2705 30
2 C 147
1 B 149 GOOG 2705 30
3 S 150 GOOG 2705 30
1 C 149
4 B 151 GOOG 2705 30
4 S 152 GOOG 2705 30
4 C 151
x
