tests/multi-thread-buy-sell-conc.in
5
o
0 B 125 GOOG 2705 30
2 B 126 GOOG 2705 50
1 S 127 GOOG 2705 30
4 S 128 GOOG 2705 50
0 B 129 GOOG 2705 30
2 B 130 GOOG 2705 50
4 S 131 GOOG 2705 30
1 S 132 GOOG 2705 50
0 B 133 GOOG 2705 30
2 B 134 GOOG 2705 50
1 S 135 GOOG 2705 30
4 S 136 GOOG 2705 50
0 B 137 GOOG 2705 30
2 B 138 GOOG 2705 50
4 S 139 GOOG 2705 30
1 S 140 GOOG 2705 50
0 B 141 GOOG 2705 30
2 B 142 GOOG 2705 50
1 S 143 GOOG 2705 30
4 S 144 GOOG 2705 50
0 B 145 GOOG 2705 30
2 B 146 GOOG 2705 50
4 S 147 GOOG 2705 30
1 S 148 GOOG 2705 50
0 B 149 GOOG 2705 30
2 B 150 GOOG 2705 50
1 S 151 GOOG 2705 30
4 S 152 GOOG 2705 50
0 B 153 GOOG 2705 30
2 B 154 GOOG 2705 50
4 S 155 GOOG 2705 30
1 S 156 GOOG 2705 50
0 B 173 GOOG 2705 30
2 B 164 GOOG 2705 50
4 S 157 GOOG 2705 30
4 S 171 GOOG 2705 50
0 B 174 GOOG 2705 30
2 B 165 GOOG 2705 50
4 S 168 GOOG 2705 30
4 S 172 GOOG 2705 50
0 B 169 GOOG 2705 30
2 B 181 GOOG 2705 50
1 S 170 GOOG 2705 30
1 S 182 GOOG 2705 50
2 B 176 GOOG 2705 30
2 B 188 GOOG 2705 50
4 S 187 GOOG 2705 30
1 S 186 GOOG 2705 50
2 B 177 GOOG 2705 30
2 B 185 GOOG 2705 50
2 S 184 GOOG 2705 30
2 S 183 GOOG 2705 50
x
