tests/multiple-add-conc-extra.in
2
o
0 B 125 GOOG 2705 30
1 B 126 GOOG 2705 30
0 B 127 GOOG 2705 30
1 B 128 GOOG 2705 30
0 B 129 GOOG 2705 30
1 B 130 GOOG 2705 30
0 B 131 GOOG 2705 30
1 B 132 GOOG 2705 30
0 B 133 GOOG 2705 30
1 B 134 GOOG 2705 30
0 B 135 GOOG 2705 30
1 B 136 GOOG 2705 30
0 B 137 GOOG 2705 30
1 B 138 GOOG 2705 30
0 B 139 GOOG 2705 30
1 B 140 GOOG 2705 30
0 B 141 GOOG 2705 30
1 B 142 GOOG 2705 30
0 B 143 GOOG 2705 30
1 B 144 GOOG 2705 30
0 B 145 GOOG 2705 30
1 B 146 GOOG 2705 30
0 B 147 GOOG 2705 30
1 B 148 GOOG 2705 30
0 B 149 GOOG 2705 30
1 B 150 GOOG 2705 30
0 B 151 GOOG 2705 30
1 B 152 GOOG 2705 30
0 B 153 GOOG 2705 30
1 B 154 GOOG 2705 30
0 B 155 GOOG 2705 30
1 B 156 GOOG 2705 30
0 B 157 GOOG 2705 30
1 B 158 GOOG 2705 30
0 B 159 GOOG 2705 30
1 B 160 GOOG 2705 30
0 B 161 GOOG 2705 30
1 B 162 GOOG 2705 30
0 B 163 GOOG 2705 30
1 B 164 GOOG 2705 30
0 B 165 GOOG 2705 30
1 B 166 GOOG 2705 30
0 B 167 GOOG 2705 30
1 B 168 GOOG 2705 30
0 B 169 GOOG 2705 30
1 B 170 GOOG 2705 30
0 B 171 GOOG 2705 30
1 B 172 GOOG 2705 30
x
