tests/over-exec-conc.in
4
o
0 B 195 GOOG 2705 50
1 S 126 GOOG 2705 60
2 B 196 GOOG 2705 50
3 S 198 GOOG 2705 60
1 B 197 GOOG 2705 50
0 S 199 GOOG 2705 60
2 B 125 GOOG 2705 50
3 S 200 GOOG 2705 60
0 B 127 GOOG 2705 50
1 S 128 GOOG 2705 60
2 B 129 GOOG 2705 50
3 S 130 GOOG 2705 60
1 B 131 GOOG 2705 50
0 S 132 GOOG 2705 60
2 B 133 GOOG 2705 50
3 S 134 GOOG 2705 60
0 B 135 GOOG 2705 50
1 S 136 GOOG 2705 60
2 B 137 GOOG 2705 50
3 S 138 GOOG 2705 60
1 B 139 GOOG 2705 50
0 S 140 GOOG 2705 60
2 B 141 GOOG 2705 50
3 S 142 GOOG 2705 60
0 B 143 GOOG 2705 50
1 S 144 GOOG 2705 60
3 B 145 GOOG 2705 50
2 S 146 GOOG 2705 60
1 B 147 GOOG 2705 50
0 S 148 GOOG 2705 60
3 B 149 GOOG 2705 50
2 S 150 GOOG 2705 60
0 B 151 GOOG 2705 50
1 S 152 GOOG 2705 60
2 B 153 GOOG 2705 50
3 S 154 GOOG 2705 60
1 B 155 GOOG 2705 50
0 S 156 GOOG 2705 60
2 B 157 GOOG 2705 50
3 S 158 GOOG 2705 60
0 B 159 GOOG 2705 50
1 S 160 GOOG 2705 60
2 B 161 GOOG 2705 50
3 S 162 GOOG 2705 60
1 B 163 GOOG 2705 50
0 S 164 GOOG 2705 60
2 B 165 GOOG 2705 50
3 S 166 GOOG 2705 60
0 B 167 GOOG 2705 50
1 S 168 GOOG 2705 60
2 B 169 GOOG 2705 50
3 S 170 GOOG 2705 60
1 B 171 GOOG 2705 50
0 S 172 GOOG 2705 60
2 B 173 GOOG 2705 50
3 S 174 GOOG 2705 60
0 B 175 GOOG 2705 50
1 S 176 GOOG 2705 60
3 B 177 GOOG 2705 50
2 S 178 GOOG 2705 60
1 B 179 GOOG 2705 50
0 S 180 GOOG 2705 60
3 B 181 GOOG 2705 50
2 S 182 GOOG 2705 60
x
