tests/pricetime-vs-time-conc.in
4
o
1 s 20
0 S 1 GOOG 2000 1
0 S 2 GOOG 2000 1
0 S 3 GOOG 1000 1
0 S 4 GOOG 1000 1
2 S 5 GOOG 2000 1
2 S 6 GOOG 2000 1
2 S 7 GOOG 1000 1
2 S 8 GOOG 1000 1
3 S 9 GOOG 2000 1
3 S 10 GOOG 2000 1
3 S 11 GOOG 1000 1
3 S 12 GOOG 1000 1
1 B 13 GOOG 5000 1
1 B 14 GOOG 5000 1
1 B 15 GOOG 5000 1
1 B 16 GOOG 5000 1
0 S 17 GOOG 2000 1
0 S 18 GOOG 2000 1
0 S 19 GOOG 1000 1
0 S 20 GOOG 1000 1
2 S 21 GOOG 2000 1
2 S 22 GOOG 2000 1
2 S 23 GOOG 1000 1
2 S 24 GOOG 1000 1
3 S 25 GOOG 2000 1
3 S 26 GOOG 2000 1
3 S 27 GOOG 1000 1
3 S 28 GOOG 1000 1
1 B 29 GOOG 5000 1
1 B 30 GOOG 5000 1
1 B 31 GOOG 5000 1
1 B 32 GOOG 5000 1
x
